<?xml version="1.0"?>

<robot name="simple_robot" xmlns:xacro="http://www.ros.org/wiki/xacro">

    <link name="world"/>

    <joint name="fixed" type="fixed">
      <parent link="world"/>
      <child link="base_link"/>
    </joint>
    <!-- Base link -->
    
    <!-- PALM -->
    <link name="base_link">
        <visual>
            <origin rpy="0.0 0.0 0.0" xyz="0.0 0.0 0.095 "/>
            <geometry>
                <mesh filename="package://simple_robot_description/meshes/base_link.dae"/>
            </geometry>
            <material name="black">
                <color rgba="0.2 0.2 0.2 1"/>
            </material>
        </visual>
        <collision>
            <!--<origin rpy="0.0 0.0 0.0" xyz="0.0 0.0 0.095"/>
            <geometry>
                <mesh filename="package://simple_robot_description/meshes/base_link.dae"/>
            </geometry>-->
            <origin rpy="0.0 0.0 0.0" xyz="0.0 0.0 0.0425"/>
            <geometry>
                <box size="0.05 0.09 0.09"/>
            </geometry>
        </collision>
        <inertial>
          <origin xyz="-0.009362 -0.000854 0.056774" rpy="0.0 0.0 0.0"/>
          <mass value="0.4154"/>
          <inertia
              ixx="0.0001" ixy="0.0" ixz="0.0"
              iyy="0.0001" iyz="0.0"
              izz="0.0001"/>
        </inertial>
    </link>

        <!-- FINGER 0 -->

    <joint name="finger0_joint_0" type="revolute">
        <parent link="base_link"/>
        <child link="finger0_link_0"/>
        <origin rpy="-0.08726646255 0 0.0082"
                xyz="0.0 0.0435 0.093"/>
        <axis xyz="0 0 1"/>
        <limit effort="15" velocity="7"
               lower="-0.57"
               upper="0.57"/>
        <dynamics damping="3" friction="10"/>
    </joint>
    <!--<joint name="finger0_joint_0" type="continuous">
        <parent link="base_link"/>
        <child link="finger0_link_0"/>
        <origin rpy="-0.08726646255 0 0.0082"
                xyz="0.0 0.0435 0.093"/>
        <axis xyz="0 0 1"/>
        <dynamics damping="0.7"/>
  </joint>-->

    <!-- [LINK 0] -->
    <link name="finger0_link_0">
        <visual>
            <origin rpy="0.0 0.0 0.0" xyz="0 0 0"/>
            <geometry>
                <mesh filename="package://simple_robot_description/meshes/link_0.0.dae"/>
            </geometry>
            <material name="black"/>
        </visual>
        <collision>
            <origin rpy="0.0 0.0 0.0" xyz="0 0 0.015"/>
            <geometry>
                <box size="0.03 0.03 0.03"/>
            </geometry>
            <!--<geometry>
                <mesh filename="package://simple_robot_description/meshes/link_0.0.dae"/>
            </geometry>-->
        </collision>
        <inertial>
          <mass value="0.0119" />
          <origin xyz="-0.0004731 -0.001 0.016" rpy="0.0 0.0 0.0"/>
          <inertia ixx="0.0001" ixy="0.0" ixz="0.0"
                   iyy="0.0001" iyz="0.0"
                   izz="0.0001" />
        </inertial>
    </link>


<!--  Finger0 joint 0 -->
  <transmission name="tran0_0">
      <type>transmission_interface/SimpleTransmission</type>
      <joint name="finger0_joint_0">
        <hardwareInterface>hardware_interface/EffortJointInterface</hardwareInterface>
      </joint>
      <actuator name="motor0_0">
        <hardwareInterface>hardware_interface/EffortJointInterface</hardwareInterface>
        <mechanicalReduction>1</mechanicalReduction>
      </actuator>
  </transmission>





<!--  //////////// Gazebo plugin //////////// -->

  <gazebo>
    <plugin name="gazebo_ros_control" filename="libgazebo_ros_control.so">
         <robotNamespace>/simple_robot</robotNamespace>
         <robotSimType>gazebo_ros_control/DefaultRobotHWSim</robotSimType>
     </plugin>
     <self_collide>1</self_collide>
  </gazebo>


</robot>
